Workbook

Sheet README
A1: Example ledger: every TRANSFER case
A3: Anonymised example that goes with the blog post on how I keep my books. All names, accounts and amounts are made up.
A4: ENTRIES holds the rows. Filter column case to see one example; the note column says what each row does.
A5: CHECKS tests the rules: TRANSFER sums to zero overall and per id, helper sources return to zero, euro amounts match fx_amount / rate.
A6: SUMMARY shows income, spending and net worth, and proves that transfers change none of them.
A7: CODES holds the lists behind the dropdowns on ENTRIES.
A8: WHEREABOUTS lists where I was: one row per arrival, with Work TRUE for a stay with a job. The dashboard uses it for the days in Asia, the groceries per stay and the Work tab.
A9: Legend
A10: Blue text | B10: Values you type (the inputs). Edit these.
A11: Black text | B11: Formulas. Leave these alone.
A12: Grey rows | B12: TRANSFER rows on ENTRIES.
A13: Signs | B13: amount is in euros, seen from the source: + is money in, - is money out.
A15: case | B15: family | C15: what happens | D15: how it is booked | E15: rows | F15: TRANSFER sum | G15: effect on income | H15: effect on spending
A16: O1 | B16: Setup | C16: Opening balances | D16: The balance of each source on the first day of the file. Not income, not a transfer. | E16: =COUNTIF(ENTRIES!$A$2:$A$2000,A16) -> 5 | F16: =ROUND(SUMIFS(ENTRIES!$E$2:$E$2000,ENTRIES!$A$2:$A$2000,A16,ENTRIES!$G$2:$G$2000,"TRANSFER"),2) -> 0 | G16: =SUMIFS(ENTRIES!$E$2:$E$2000,ENTRIES!$A$2:$A$2000,A16,ENTRIES!$G$2:$G$2000,"IN") -> 0 | H16: =SUMPRODUCT((ENTRIES!$A$2:$A$2000=A16)*(LEFT(ENTRIES!$G$2:$G$2000,3)="OUT"),ENTRIES!$E$2:$E$2000) -> 0
A17: B0 | B17: Background | C17: Ordinary rows | D17: Normal income and spending, so the example balances look like a real season. | E17: =COUNTIF(ENTRIES!$A$2:$A$2000,A17) -> 641 | F17: =ROUND(SUMIFS(ENTRIES!$E$2:$E$2000,ENTRIES!$A$2:$A$2000,A17,ENTRIES!$G$2:$G$2000,"TRANSFER"),2) -> 0 | G17: =SUMIFS(ENTRIES!$E$2:$E$2000,ENTRIES!$A$2:$A$2000,A17,ENTRIES!$G$2:$G$2000,"IN") -> 4957.3 | H17: =SUMPRODUCT((ENTRIES!$A$2:$A$2000=A17)*(LEFT(ENTRIES!$G$2:$G$2000,3)="OUT"),ENTRIES!$E$2:$E$2000) -> -3788.38
A18: T01 | B18: A. Between my own sources | C18: Saving: current account to savings | D18: The classic pair. Two legs, same id, opposite amounts. | E18: =COUNTIF(ENTRIES!$A$2:$A$2000,A18) -> 4 | F18: =ROUND(SUMIFS(ENTRIES!$E$2:$E$2000,ENTRIES!$A$2:$A$2000,A18,ENTRIES!$G$2:$G$2000,"TRANSFER"),2) -> 0 | G18: =SUMIFS(ENTRIES!$E$2:$E$2000,ENTRIES!$A$2:$A$2000,A18,ENTRIES!$G$2:$G$2000,"IN") -> 0 | H18: =SUMPRODUCT((ENTRIES!$A$2:$A$2000=A18)*(LEFT(ENTRIES!$G$2:$G$2000,3)="OUT"),ENTRIES!$E$2:$E$2000) -> 0
A19: T02 | B19: A. Between my own sources | C19: Cash from a home ATM | D19: Cash is a source like any other, so a withdrawal is a transfer, not spending. | E19: =COUNTIF(ENTRIES!$A$2:$A$2000,A19) -> 2 | F19: =ROUND(SUMIFS(ENTRIES!$E$2:$E$2000,ENTRIES!$A$2:$A$2000,A19,ENTRIES!$G$2:$G$2000,"TRANSFER"),2) -> 0 | G19: =SUMIFS(ENTRIES!$E$2:$E$2000,ENTRIES!$A$2:$A$2000,A19,ENTRIES!$G$2:$G$2000,"IN") -> 0 | H19: =SUMPRODUCT((ENTRIES!$A$2:$A$2000=A19)*(LEFT(ENTRIES!$G$2:$G$2000,3)="OUT"),ENTRIES!$E$2:$E$2000) -> 0
A20: T03 | B20: A. Between my own sources | C20: ATM abroad, with a local ATM fee | D20: Book the transfer at the euro amount the bank charged and the gross local amount; the fee is a negative expense row inside the cash wallet. | E20: =COUNTIF(ENTRIES!$A$2:$A$2000,A20) -> 3 | F20: =ROUND(SUMIFS(ENTRIES!$E$2:$E$2000,ENTRIES!$A$2:$A$2000,A20,ENTRIES!$G$2:$G$2000,"TRANSFER"),2) -> 0 | G20: =SUMIFS(ENTRIES!$E$2:$E$2000,ENTRIES!$A$2:$A$2000,A20,ENTRIES!$G$2:$G$2000,"IN") -> 0 | H20: =SUMPRODUCT((ENTRIES!$A$2:$A$2000=A20)*(LEFT(ENTRIES!$G$2:$G$2000,3)="OUT"),ENTRIES!$E$2:$E$2000) -> -6.77
A21: T04 | B21: A. Between my own sources | C21: Exchange inside a multi-currency app | D21: One source per currency pocket. The exchange is a transfer between two of them. | E21: =COUNTIF(ENTRIES!$A$2:$A$2000,A21) -> 4 | F21: =ROUND(SUMIFS(ENTRIES!$E$2:$E$2000,ENTRIES!$A$2:$A$2000,A21,ENTRIES!$G$2:$G$2000,"TRANSFER"),2) -> 0 | G21: =SUMIFS(ENTRIES!$E$2:$E$2000,ENTRIES!$A$2:$A$2000,A21,ENTRIES!$G$2:$G$2000,"IN") -> 0 | H21: =SUMPRODUCT((ENTRIES!$A$2:$A$2000=A21)*(LEFT(ENTRIES!$G$2:$G$2000,3)="OUT"),ENTRIES!$E$2:$E$2000) -> 0
A22: T05 | B22: A. Between my own sources | C22: Credit card: purchase, then monthly settlement | D22: The purchase is the expense, on the card. The settlement from the bank is only a transfer. | E22: =COUNTIF(ENTRIES!$A$2:$A$2000,A22) -> 3 | F22: =ROUND(SUMIFS(ENTRIES!$E$2:$E$2000,ENTRIES!$A$2:$A$2000,A22,ENTRIES!$G$2:$G$2000,"TRANSFER"),2) -> 0 | G22: =SUMIFS(ENTRIES!$E$2:$E$2000,ENTRIES!$A$2:$A$2000,A22,ENTRIES!$G$2:$G$2000,"IN") -> 0 | H22: =SUMPRODUCT((ENTRIES!$A$2:$A$2000=A22)*(LEFT(ENTRIES!$G$2:$G$2000,3)="OUT"),ENTRIES!$E$2:$E$2000) -> -612.4
A23: T06 | B23: A. Between my own sources | C23: Top up an online bank, pay a fee, pay rent | D23: Top-up is a transfer; the service fee is an expense; the rent is an expense. Three rows on the online bank, one on the bank. | E23: =COUNTIF(ENTRIES!$A$2:$A$2000,A23) -> 4 | F23: =ROUND(SUMIFS(ENTRIES!$E$2:$E$2000,ENTRIES!$A$2:$A$2000,A23,ENTRIES!$G$2:$G$2000,"TRANSFER"),2) -> 0 | G23: =SUMIFS(ENTRIES!$E$2:$E$2000,ENTRIES!$A$2:$A$2000,A23,ENTRIES!$G$2:$G$2000,"IN") -> 0 | H23: =SUMPRODUCT((ENTRIES!$A$2:$A$2000=A23)*(LEFT(ENTRIES!$G$2:$G$2000,3)="OUT"),ENTRIES!$E$2:$E$2000) -> -126.45
A24: T07 | B24: A. Between my own sources | C24: A transfer that arrives short | D24: The bank shows one line of -150. I split it: -149.50 transfer and -0.50 fee, same id. The legs stay equal. | E24: =COUNTIF(ENTRIES!$A$2:$A$2000,A24) -> 3 | F24: =ROUND(SUMIFS(ENTRIES!$E$2:$E$2000,ENTRIES!$A$2:$A$2000,A24,ENTRIES!$G$2:$G$2000,"TRANSFER"),2) -> 0 | G24: =SUMIFS(ENTRIES!$E$2:$E$2000,ENTRIES!$A$2:$A$2000,A24,ENTRIES!$G$2:$G$2000,"IN") -> 0 | H24: =SUMPRODUCT((ENTRIES!$A$2:$A$2000=A24)*(LEFT(ENTRIES!$G$2:$G$2000,3)="OUT"),ENTRIES!$E$2:$E$2000) -> -0.5
A25: T08 | B25: A. Between my own sources | C25: Cash-to-cash exchange at an airport | D25: Leftover dollars swapped for dirhams during a layover. Both legs in euros, each with its own local amount and rate. | E25: =COUNTIF(ENTRIES!$A$2:$A$2000,A25) -> 2 | F25: =ROUND(SUMIFS(ENTRIES!$E$2:$E$2000,ENTRIES!$A$2:$A$2000,A25,ENTRIES!$G$2:$G$2000,"TRANSFER"),2) -> 0 | G25: =SUMIFS(ENTRIES!$E$2:$E$2000,ENTRIES!$A$2:$A$2000,A25,ENTRIES!$G$2:$G$2000,"IN") -> 0 | H25: =SUMPRODUCT((ENTRIES!$A$2:$A$2000=A25)*(LEFT(ENTRIES!$G$2:$G$2000,3)="OUT"),ENTRIES!$E$2:$E$2000) -> 0
A26: T09 | B26: A. Between my own sources | C26: A transfer that crosses a month boundary | D26: Each leg gets the date it happened on its own source. January shows -500, February +500, the pair is zero. | E26: =COUNTIF(ENTRIES!$A$2:$A$2000,A26) -> 2 | F26: =ROUND(SUMIFS(ENTRIES!$E$2:$E$2000,ENTRIES!$A$2:$A$2000,A26,ENTRIES!$G$2:$G$2000,"TRANSFER"),2) -> 0 | G26: =SUMIFS(ENTRIES!$E$2:$E$2000,ENTRIES!$A$2:$A$2000,A26,ENTRIES!$G$2:$G$2000,"IN") -> 0 | H26: =SUMPRODUCT((ENTRIES!$A$2:$A$2000=A26)*(LEFT(ENTRIES!$G$2:$G$2000,3)="OUT"),ENTRIES!$E$2:$E$2000) -> 0
A27: T10 | B27: A. Between my own sources | C27: Rate adjusted so both legs are equal | D27: The app credited 3,690 THB for 100.00 EUR. I set the rate on the THB leg by hand to 3,690 / 100 = 36.90, so both legs are exactly 100.00. | E27: =COUNTIF(ENTRIES!$A$2:$A$2000,A27) -> 2 | F27: =ROUND(SUMIFS(ENTRIES!$E$2:$E$2000,ENTRIES!$A$2:$A$2000,A27,ENTRIES!$G$2:$G$2000,"TRANSFER"),2) -> 0 | G27: =SUMIFS(ENTRIES!$E$2:$E$2000,ENTRIES!$A$2:$A$2000,A27,ENTRIES!$G$2:$G$2000,"IN") -> 0 | H27: =SUMPRODUCT((ENTRIES!$A$2:$A$2000=A27)*(LEFT(ENTRIES!$G$2:$G$2000,3)="OUT"),ENTRIES!$E$2:$E$2000) -> 0
... A50: Z4 | B50: E. Housekeeping rows | C50: Year-end checkpoint | D50: On 31 December a zero row per source with the balance in the description. Next year I can see at once whether old rows were changed. | E50: =COUNTIF(ENTRIES!$A$2:$A$2000,A50) -> 3 | F50: =ROUND(SUMIFS(ENTRIES!$E$2:$E$2000,ENTRIES!$A$2:$A$2000,A50,ENTRIES!$G$2:$G$2000,"TRANSFER"),2) -> 0 | G50: =SUMIFS(ENTRIES!$E$2:$E$2000,ENTRIES!$A$2:$A$2000,A50,ENTRIES!$G$2:$G$2000,"IN") -> 0 | H50: =SUMPRODUCT((ENTRIES!$A$2:$A$2000=A50)*(LEFT(ENTRIES!$G$2:$G$2000,3)="OUT"),ENTRIES!$E$2:$E$2000) -> 0
A52: Effect on spending uses the sign of amount: negative = this case adds to spending (money out), positive = it reduces spending. Transfers add nothing.

Sheet ENTRIES
A1: case | B1: id | C1: source | D1: date | E1: amount | F1: description | G1: type | H1: group | I1: category | J1: daily_code | K1: fx_amount | L1: currency | M1: rate | N1: fx_check | O1: month | P1: note
A2: O1 | B2: 100 | C2: BANK_CURRENT | D2: 45961 | E2: 6600 | F2: opening balance | G2: OPENING_BALANCE | H2: OPENING_BALANCE | I2: opening_balance | N2: =IF(OR(K2="",M2=""),"",IF(C2="STATS_ONLY","stats",IF(ROUND(K2/M2,2)=E2,"OK","CHECK"))) | O2: =TEXT(D2,"yyyy-mm") -> 2025-10 | P2: first row of every source
A3: O1 | B3: 100 | C3: BANK_SAVINGS | D3: 45961 | E3: 8000 | F3: opening balance | G3: OPENING_BALANCE | H3: OPENING_BALANCE | I3: opening_balance | N3: =IF(OR(K3="",M3=""),"",IF(C3="STATS_ONLY","stats",IF(ROUND(K3/M3,2)=E3,"OK","CHECK"))) | O3: =TEXT(D3,"yyyy-mm") -> 2025-10 | P3: first row of every source
A4: O1 | B4: 100 | C4: BANK_PENSION | D4: 45961 | E4: 2400 | F4: opening balance | G4: OPENING_BALANCE | H4: OPENING_BALANCE | I4: opening_balance | N4: =IF(OR(K4="",M4=""),"",IF(C4="STATS_ONLY","stats",IF(ROUND(K4/M4,2)=E4,"OK","CHECK"))) | O4: =TEXT(D4,"yyyy-mm") -> 2025-10 | P4: first row of every source
A5: O1 | B5: 100 | C5: CASH_EUR | D5: 45961 | E5: 150 | F5: opening balance | G5: OPENING_BALANCE | H5: OPENING_BALANCE | I5: opening_balance | N5: =IF(OR(K5="",M5=""),"",IF(C5="STATS_ONLY","stats",IF(ROUND(K5/M5,2)=E5,"OK","CHECK"))) | O5: =TEXT(D5,"yyyy-mm") -> 2025-10 | P5: first row of every source
A6: O1 | B6: 100 | C6: CASH_USD | D6: 45961 | E6: 51.24 | F6: opening balance | G6: OPENING_BALANCE | H6: OPENING_BALANCE | I6: opening_balance | K6: 60 | L6: USD | M6: 1.1709602 | N6: =IF(OR(K6="",M6=""),"",IF(C6="STATS_ONLY","stats",IF(ROUND(K6/M6,2)=E6,"OK","CHECK"))) -> OK | O6: =TEXT(D6,"yyyy-mm") -> 2025-10 | P6: first row of every source
A7: B0 | B7: 9589 | C7: BANK_CURRENT | D7: 45962 | E7: -15 | F7: mobile provider | G7: OUT_FIXED | H7: FIXED_COSTS | I7: phone_internet | N7: =IF(OR(K7="",M7=""),"",IF(C7="STATS_ONLY","stats",IF(ROUND(K7/M7,2)=E7,"OK","CHECK"))) | O7: =TEXT(D7,"yyyy-mm") -> 2025-11
A8: B0 | B8: 9590 | C8: BANK_CURRENT | D8: 45962 | E8: -100 | F8: monthly to pension savings | G8: TRANSFER | H8: TRANSFER | I8: transfer | N8: =IF(OR(K8="",M8=""),"",IF(C8="STATS_ONLY","stats",IF(ROUND(K8/M8,2)=E8,"OK","CHECK"))) | O8: =TEXT(D8,"yyyy-mm") -> 2025-11 | P8: leg out
A9: B0 | B9: 9590 | C9: BANK_PENSION | D9: 45962 | E9: 100 | F9: monthly to pension savings | G9: TRANSFER | H9: TRANSFER | I9: transfer | N9: =IF(OR(K9="",M9=""),"",IF(C9="STATS_ONLY","stats",IF(ROUND(K9/M9,2)=E9,"OK","CHECK"))) | O9: =TEXT(D9,"yyyy-mm") -> 2025-11 | P9: leg in
A10: B0 | B10: 9659 | C10: CREDIT_CARD | D10: 45963 | E10: -142 | F10: travel insurance winter | G10: OUT_ASIA_INSURANCE | H10: ASIA_PREP | I10: travel_insurance | N10: =IF(OR(K10="",M10=""),"",IF(C10="STATS_ONLY","stats",IF(ROUND(K10/M10,2)=E10,"OK","CHECK"))) | O10: =TEXT(D10,"yyyy-mm") -> 2025-11
A11: B0 | B11: 9009 | C11: CASH_AED | D11: 45965 | E11: -51.24 | F11: food and water at the airport | G11: OUT_ASIA | H11: ASIA_MISC | I11: airport | J11: s | K11: -220 | L11: AED | M11: 4.2935207 | N11: =IF(OR(K11="",M11=""),"",IF(C11="STATS_ONLY","stats",IF(ROUND(K11/M11,2)=E11,"OK","CHECK"))) -> OK | O11: =TEXT(D11,"yyyy-mm") -> 2025-11
A12: B0 | B12: 9657 | C12: BANK_CURRENT | D12: 45965 | E12: -18.9 | F12: airport train | G12: OUT | H12: TRAVEL_NL | I12: train | N12: =IF(OR(K12="",M12=""),"",IF(C12="STATS_ONLY","stats",IF(ROUND(K12/M12,2)=E12,"OK","CHECK"))) | O12: =TEXT(D12,"yyyy-mm") -> 2025-11
A13: B0 | B13: 9101 | C13: CASH_THB | D13: 45966 | E13: -176.1 | F13: room, month | G13: OUT_ASIA | H13: ASIA_DAILY | I13: housing | J13: h | K13: -6500 | L13: THB | M13: 36.910335 | N13: =IF(OR(K13="",M13=""),"",IF(C13="STATS_ONLY","stats",IF(ROUND(K13/M13,2)=E13,"OK","CHECK"))) -> OK | O13: =TEXT(D13,"yyyy-mm") -> 2025-11
A14: B0 | B14: 9102 | C14: CASH_THB | D14: 45966 | E14: -2.71 | F14: eggs and toast | G14: OUT_ASIA | H14: ASIA_DAILY | I14: daily_spending | J14: bf | K14: -100 | L14: THB | M14: 36.910335 | N14: =IF(OR(K14="",M14=""),"",IF(C14="STATS_ONLY","stats",IF(ROUND(K14/M14,2)=E14,"OK","CHECK"))) -> OK | O14: =TEXT(D14,"yyyy-mm") -> 2025-11
A15: B0 | B15: 9103 | C15: CASH_THB | D15: 45966 | E15: -2.84 | F15: massaman curry | G15: OUT_ASIA | H15: ASIA_DAILY | I15: daily_spending | J15: d | K15: -105 | L15: THB | M15: 36.910335 | N15: =IF(OR(K15="",M15=""),"",IF(C15="STATS_ONLY","stats",IF(ROUND(K15/M15,2)=E15,"OK","CHECK"))) -> OK | O15: =TEXT(D15,"yyyy-mm") -> 2025-11
A16: B0 | B16: 9104 | C16: CASH_THB | D16: 45966 | E16: -1.63 | F16: americano | G16: OUT_ASIA | H16: ASIA_DAILY | I16: daily_spending | J16: c | K16: -60 | L16: THB | M16: 36.910335 | N16: =IF(OR(K16="",M16=""),"",IF(C16="STATS_ONLY","stats",IF(ROUND(K16/M16,2)=E16,"OK","CHECK"))) -> OK | O16: =TEXT(D16,"yyyy-mm") -> 2025-11
A17: B0 | B17: 9591 | C17: BANK_CURRENT | D17: 45966 | E17: -45 | F17: storage unit | G17: OUT_FIXED | H17: FIXED_COSTS | I17: storage_unit | N17: =IF(OR(K17="",M17=""),"",IF(C17="STATS_ONLY","stats",IF(ROUND(K17/M17,2)=E17,"OK","CHECK"))) | O17: =TEXT(D17,"yyyy-mm") -> 2025-11
A18: B0 | B18: 9105 | C18: BANK_CURRENT | D18: 45967 | E18: -277.18 | F18: ATM withdrawal 277.18 EUR = 10,250 THB (10,000 + 250 fee) | G18: TRANSFER | H18: TRANSFER | I18: transfer | N18: =IF(OR(K18="",M18=""),"",IF(C18="STATS_ONLY","stats",IF(ROUND(K18/M18,2)=E18,"OK","CHECK"))) | O18: =TEXT(D18,"yyyy-mm") -> 2025-11 | P18: leg out
A19: B0 | B19: 9105 | C19: CASH_THB | D19: 45967 | E19: 277.18 | F19: ATM withdrawal 277.18 EUR = 10,250 THB (10,000 + 250 fee) | G19: TRANSFER | H19: TRANSFER | I19: transfer | J19: in | K19: 10250 | L19: THB | M19: =K19/E19 -> 36.97958 | N19: =IF(OR(K19="",M19=""),"",IF(C19="STATS_ONLY","stats",IF(ROUND(K19/M19,2)=E19,"OK","CHECK"))) -> OK | O19: =TEXT(D19,"yyyy-mm") -> 2025-11 | P19: leg in
A20: B0 | B20: 9105 | C20: CASH_THB | D20: 45967 | E20: -6.76 | F20: ATM fee 250 THB | G20: OUT_ASIA | H20: ASIA_DAILY | I20: bank_fees_asia | J20: misc | K20: -250 | L20: THB | M20: 36.97958 | N20: =IF(OR(K20="",M20=""),"",IF(C20="STATS_ONLY","stats",IF(ROUND(K20/M20,2)=E20,"OK","CHECK"))) -> OK | O20: =TEXT(D20,"yyyy-mm") -> 2025-11 | P20: cost split off, same id, negative
A21: B0 | B21: 9106 | C21: CASH_THB | D21: 45967 | E21: -2.16 | F21: noodle soup | G21: OUT_ASIA | H21: ASIA_DAILY | I21: daily_spending | J21: l | K21: -80 | L21: THB | M21: 36.97958 | N21: =IF(OR(K21="",M21=""),"",IF(C21="STATS_ONLY","stats",IF(ROUND(K21/M21,2)=E21,"OK","CHECK"))) -> OK | O21: =TEXT(D21,"yyyy-mm") -> 2025-11
A22: B0 | B22: 9107 | C22: CASH_THB | D22: 45967 | E22: -4.46 | F22: massaman curry | G22: OUT_ASIA | H22: ASIA_DAILY | I22: daily_spending | J22: d | K22: -165 | L22: THB | M22: 36.97958 | N22: =IF(OR(K22="",M22=""),"",IF(C22="STATS_ONLY","stats",IF(ROUND(K22/M22,2)=E22,"OK","CHECK"))) -> OK | O22: =TEXT(D22,"yyyy-mm") -> 2025-11
A23: B0 | B23: 9002 | C23: CASH_THB | D23: 45968 | E23: -2.71 | F23: pad thai | G23: OUT_ASIA | H23: ASIA_DAILY | I23: daily_spending | J23: d | K23: -100 | L23: THB | M23: 36.910335 | N23: =IF(OR(K23="",M23=""),"",IF(C23="STATS_ONLY","stats",IF(ROUND(K23/M23,2)=E23,"OK","CHECK"))) -> OK | O23: =TEXT(D23,"yyyy-mm") -> 2025-11
A24: B0 | B24: 9003 | C24: CASH_THB | D24: 45968 | E24: -1.63 | F24: iced latte | G24: OUT_ASIA | H24: ASIA_DAILY | I24: daily_spending | J24: c | K24: -60 | L24: THB | M24: 36.910335 | N24: =IF(OR(K24="",M24=""),"",IF(C24="STATS_ONLY","stats",IF(ROUND(K24/M24,2)=E24,"OK","CHECK"))) -> OK | O24: =TEXT(D24,"yyyy-mm") -> 2025-11
A25: B0 | B25: 9108 | C25: CASH_THB | D25: 45968 | E25: -1.35 | F25: fruit shake | G25: OUT_ASIA | H25: ASIA_DAILY | I25: daily_spending | J25: s | K25: -50 | L25: THB | M25: 36.97958 | N25: =IF(OR(K25="",M25=""),"",IF(C25="STATS_ONLY","stats",IF(ROUND(K25/M25,2)=E25,"OK","CHECK"))) -> OK | O25: =TEXT(D25,"yyyy-mm") -> 2025-11
A26: B0 | B26: 9592 | C26: MULTI_EUR | D26: 45968 | E26: -21.78 | F26: AI assistant subscription | G26: OUT_FIXED | H26: FIXED_COSTS | I26: ai_tools | N26: =IF(OR(K26="",M26=""),"",IF(C26="STATS_ONLY","stats",IF(ROUND(K26/M26,2)=E26,"OK","CHECK"))) | O26: =TEXT(D26,"yyyy-mm") -> 2025-11
A27: B0 | B27: 9109 | C27: CASH_THB | D27: 45969 | E27: -2.84 | F27: fruit plate | G27: OUT_ASIA | H27: ASIA_DAILY | I27: daily_spending | J27: bf | K27: -105 | L27: THB | M27: 36.97958 | N27: =IF(OR(K27="",M27=""),"",IF(C27="STATS_ONLY","stats",IF(ROUND(K27/M27,2)=E27,"OK","CHECK"))) -> OK | O27: =TEXT(D27,"yyyy-mm") -> 2025-11
A28: B0 | B28: 9110 | C28: CASH_THB | D28: 45969 | E28: -2.03 | F28: fried rice | G28: OUT_ASIA | H28: ASIA_DAILY | I28: daily_spending | J28: l | K28: -75 | L28: THB | M28: 36.97958 | N28: =IF(OR(K28="",M28=""),"",IF(C28="STATS_ONLY","stats",IF(ROUND(K28/M28,2)=E28,"OK","CHECK"))) -> OK | O28: =TEXT(D28,"yyyy-mm") -> 2025-11
A29: B0 | B29: 9111 | C29: CASH_THB | D29: 45969 | E29: -3.52 | F29: massaman curry | G29: OUT_ASIA | H29: ASIA_DAILY | I29: daily_spending | J29: d | K29: -130 | L29: THB | M29: 36.97958 | N29: =IF(OR(K29="",M29=""),"",IF(C29="STATS_ONLY","stats",IF(ROUND(K29/M29,2)=E29,"OK","CHECK"))) -> OK | O29: =TEXT(D29,"yyyy-mm") -> 2025-11
A30: B0 | B30: 9112 | C30: CASH_THB | D30: 45969 | E30: -1.76 | F30: espresso | G30: OUT_ASIA | H30: ASIA_DAILY | I30: daily_spending | J30: c | K30: -65 | L30: THB | M30: 36.97958 | N30: =IF(OR(K30="",M30=""),"",IF(C30="STATS_ONLY","stats",IF(ROUND(K30/M30,2)=E30,"OK","CHECK"))) -> OK | O30: =TEXT(D30,"yyyy-mm") -> 2025-11
A31: B0 | B31: 9593 | C31: BANK_CURRENT | D31: 45969 | E31: -2.99 | F31: cloud storage | G31: OUT_FIXED | H31: FIXED_COSTS | I31: cloud_storage | N31: =IF(OR(K31="",M31=""),"",IF(C31="STATS_ONLY","stats",IF(ROUND(K31/M31,2)=E31,"OK","CHECK"))) | O31: =TEXT(D31,"yyyy-mm") -> 2025-11
A32: B0 | B32: 9113 | C32: CASH_THB | D32: 45971 | E32: -3.52 | F32: fried rice | G32: OUT_ASIA | H32: ASIA_DAILY | I32: daily_spending | J32: l | K32: -130 | L32: THB | M32: 36.97958 | N32: =IF(OR(K32="",M32=""),"",IF(C32="STATS_ONLY","stats",IF(ROUND(K32/M32,2)=E32,"OK","CHECK"))) -> OK | O32: =TEXT(D32,"yyyy-mm") -> 2025-11
A33: B0 | B33: 9114 | C33: CASH_THB | D33: 45971 | E33: -1.49 | F33: flat white | G33: OUT_ASIA | H33: ASIA_DAILY | I33: daily_spending | J33: c | K33: -55 | L33: THB | M33: 36.97958 | N33: =IF(OR(K33="",M33=""),"",IF(C33="STATS_ONLY","stats",IF(ROUND(K33/M33,2)=E33,"OK","CHECK"))) -> OK | O33: =TEXT(D33,"yyyy-mm") -> 2025-11
A34: B0 | B34: 9115 | C34: CASH_THB | D34: 45971 | E34: -0.54 | F34: mango | G34: OUT_ASIA | H34: ASIA_DAILY | I34: daily_spending | J34: s | K34: -20 | L34: THB | M34: 36.97958 | N34: =IF(OR(K34="",M34=""),"",IF(C34="STATS_ONLY","stats",IF(ROUND(K34/M34,2)=E34,"OK","CHECK"))) -> OK | O34: =TEXT(D34,"yyyy-mm") -> 2025-11
A35: B0 | B35: 9116 | C35: CASH_THB | D35: 45972 | E35: -2.3 | F35: flat white | G35: OUT_ASIA | H35: ASIA_DAILY | I35: daily_spending | J35: c | K35: -85 | L35: THB | M35: 36.97958 | N35: =IF(OR(K35="",M35=""),"",IF(C35="STATS_ONLY","stats",IF(ROUND(K35/M35,2)=E35,"OK","CHECK"))) -> OK | O35: =TEXT(D35,"yyyy-mm") -> 2025-11
A36: B0 | B36: 9117 | C36: CASH_THB | D36: 45972 | E36: -1.62 | F36: mango | G36: OUT_ASIA | H36: ASIA_DAILY | I36: daily_spending | J36: s | K36: -60 | L36: THB | M36: 36.97958 | N36: =IF(OR(K36="",M36=""),"",IF(C36="STATS_ONLY","stats",IF(ROUND(K36/M36,2)=E36,"OK","CHECK"))) -> OK | O36: =TEXT(D36,"yyyy-mm") -> 2025-11
A37: B0 | B37: 9118 | C37: CASH_THB | D37: 45973 | E37: -2.84 | F37: eggs and toast | G37: OUT_ASIA | H37: ASIA_DAILY | I37: daily_spending | J37: bf | K37: -105 | L37: THB | M37: 36.97958 | N37: =IF(OR(K37="",M37=""),"",IF(C37="STATS_ONLY","stats",IF(ROUND(K37/M37,2)=E37,"OK","CHECK"))) -> OK | O37: =TEXT(D37,"yyyy-mm") -> 2025-11
A38: B0 | B38: 9119 | C38: CASH_THB | D38: 45973 | E38: -1.62 | F38: flat white | G38: OUT_ASIA | H38: ASIA_DAILY | I38: daily_spending | J38: c | K38: -60 | L38: THB | M38: 36.97958 | N38: =IF(OR(K38="",M38=""),"",IF(C38="STATS_ONLY","stats",IF(ROUND(K38/M38,2)=E38,"OK","CHECK"))) -> OK | O38: =TEXT(D38,"yyyy-mm") -> 2025-11
A39: B0 | B39: 9120 | C39: CASH_THB | D39: 45973 | E39: -3.38 | F39: sunscreen | G39: OUT_ASIA | H39: ASIA_DAILY | I39: daily_spending | J39: misc | K39: -125 | L39: THB | M39: 36.97958 | N39: =IF(OR(K39="",M39=""),"",IF(C39="STATS_ONLY","stats",IF(ROUND(K39/M39,2)=E39,"OK","CHECK"))) -> OK | O39: =TEXT(D39,"yyyy-mm") -> 2025-11
A40: B0 | B40: 9121 | C40: CASH_THB | D40: 45974 | E40: -1.89 | F40: smoothie bowl | G40: OUT_ASIA | H40: ASIA_DAILY | I40: daily_spending | J40: bf | K40: -70 | L40: THB | M40: 36.97958 | N40: =IF(OR(K40="",M40=""),"",IF(C40="STATS_ONLY","stats",IF(ROUND(K40/M40,2)=E40,"OK","CHECK"))) -> OK | O40: =TEXT(D40,"yyyy-mm") -> 2025-11
...

Sheet CHECKS
A1: Checks
A2: All formulas read ENTRIES. A check passes when its status reads OK.
A4: # | B4: check | C4: value | D4: status | E4: what a failure usually means
A5: 1 | B5: Sum of all TRANSFER rows | C5: =ROUND(SUMIFS(ENTRIES!$E$2:$E$2000,ENTRIES!$G$2:$G$2000,"TRANSFER"),2) -> 0 | D5: =IF(ABS(C5)<0.005,"OK","CHECK") -> OK | E5: A leg is missing, doubled or has the wrong sign
A6: 2 | B6: TRANSFER ids that do not sum to zero | C6: =COUNTIF($D$18:$D$78,"CHECK") -> 0 | D6: =IF(C6=0,"OK","CHECK") -> OK | E6: See the per-id table below for the exact pair
A7: 3 | B7: Months whose TRANSFER sum is not zero | C7: =COUNTIF($D$83:$D$91,"<>OK") -> 2 | D7: =IF(C7=0,"OK","REVIEW") -> REVIEW | E7: A pair with legs in different months (T09, T12): fine if explained
A8: 4 | B8: Helper sources not at zero | C8: =COUNTIFS($C$96:$C$121,"helper",$F$96:$F$121,"CHECK") -> 0 | D8: =IF(C8=0,"OK","CHECK") -> OK | E8: An open claim, tab or prepayment: fine if you know what it is
A9: 5 | B9: Rows where amount is not exactly ROUND(fx_amount / rate, 2) | C9: =COUNTIF(ENTRIES!$N$2:$N$2000,"CHECK") -> 0 | D9: =IF(C9=0,"OK","CHECK") -> OK | E9: A typo or a wrong sign; adjust the amount by hand so the difference is 0
A10: 6 | B10: Real sources vs statement, app or cash count | C10: manual | E10: Compare the balance table below with the outside world
A11: 7 | B11: Bank statement line by line | C11: manual | E11: Load the bank CSV in the reconciliation tool
A16: Check 2 · TRANSFER sum per id
A17: id | B17: case | C17: TRANSFER sum | D17: status | E17: rows
A18: 101 | B18: =INDEX(ENTRIES!$A$2:$A$2000,MATCH(A18,ENTRIES!$B$2:$B$2000,0)) -> T01 | C18: =ROUND(SUMIFS(ENTRIES!$E$2:$E$2000,ENTRIES!$B$2:$B$2000,A18,ENTRIES!$G$2:$G$2000,"TRANSFER"),2) -> 0 | D18: =IF(ABS(C18)<0.005,"OK","CHECK") -> OK | E18: =COUNTIFS(ENTRIES!$B$2:$B$2000,A18,ENTRIES!$G$2:$G$2000,"TRANSFER") -> 2
A19: 102 | B19: =INDEX(ENTRIES!$A$2:$A$2000,MATCH(A19,ENTRIES!$B$2:$B$2000,0)) -> T01 | C19: =ROUND(SUMIFS(ENTRIES!$E$2:$E$2000,ENTRIES!$B$2:$B$2000,A19,ENTRIES!$G$2:$G$2000,"TRANSFER"),2) -> 0 | D19: =IF(ABS(C19)<0.005,"OK","CHECK") -> OK | E19: =COUNTIFS(ENTRIES!$B$2:$B$2000,A19,ENTRIES!$G$2:$G$2000,"TRANSFER") -> 2
A20: 201 | B20: =INDEX(ENTRIES!$A$2:$A$2000,MATCH(A20,ENTRIES!$B$2:$B$2000,0)) -> T02 | C20: =ROUND(SUMIFS(ENTRIES!$E$2:$E$2000,ENTRIES!$B$2:$B$2000,A20,ENTRIES!$G$2:$G$2000,"TRANSFER"),2) -> 0 | D20: =IF(ABS(C20)<0.005,"OK","CHECK") -> OK | E20: =COUNTIFS(ENTRIES!$B$2:$B$2000,A20,ENTRIES!$G$2:$G$2000,"TRANSFER") -> 2
A21: 301 | B21: =INDEX(ENTRIES!$A$2:$A$2000,MATCH(A21,ENTRIES!$B$2:$B$2000,0)) -> T03 | C21: =ROUND(SUMIFS(ENTRIES!$E$2:$E$2000,ENTRIES!$B$2:$B$2000,A21,ENTRIES!$G$2:$G$2000,"TRANSFER"),2) -> 0 | D21: =IF(ABS(C21)<0.005,"OK","CHECK") -> OK | E21: =COUNTIFS(ENTRIES!$B$2:$B$2000,A21,ENTRIES!$G$2:$G$2000,"TRANSFER") -> 2
A22: 401 | B22: =INDEX(ENTRIES!$A$2:$A$2000,MATCH(A22,ENTRIES!$B$2:$B$2000,0)) -> T04 | C22: =ROUND(SUMIFS(ENTRIES!$E$2:$E$2000,ENTRIES!$B$2:$B$2000,A22,ENTRIES!$G$2:$G$2000,"TRANSFER"),2) -> 0 | D22: =IF(ABS(C22)<0.005,"OK","CHECK") -> OK | E22: =COUNTIFS(ENTRIES!$B$2:$B$2000,A22,ENTRIES!$G$2:$G$2000,"TRANSFER") -> 2
A23: 402 | B23: =INDEX(ENTRIES!$A$2:$A$2000,MATCH(A23,ENTRIES!$B$2:$B$2000,0)) -> T04 | C23: =ROUND(SUMIFS(ENTRIES!$E$2:$E$2000,ENTRIES!$B$2:$B$2000,A23,ENTRIES!$G$2:$G$2000,"TRANSFER"),2) -> 0 | D23: =IF(ABS(C23)<0.005,"OK","CHECK") -> OK | E23: =COUNTIFS(ENTRIES!$B$2:$B$2000,A23,ENTRIES!$G$2:$G$2000,"TRANSFER") -> 2
A24: 502 | B24: =INDEX(ENTRIES!$A$2:$A$2000,MATCH(A24,ENTRIES!$B$2:$B$2000,0)) -> T05 | C24: =ROUND(SUMIFS(ENTRIES!$E$2:$E$2000,ENTRIES!$B$2:$B$2000,A24,ENTRIES!$G$2:$G$2000,"TRANSFER"),2) -> 0 | D24: =IF(ABS(C24)<0.005,"OK","CHECK") -> OK | E24: =COUNTIFS(ENTRIES!$B$2:$B$2000,A24,ENTRIES!$G$2:$G$2000,"TRANSFER") -> 2
A25: 601 | B25: =INDEX(ENTRIES!$A$2:$A$2000,MATCH(A25,ENTRIES!$B$2:$B$2000,0)) -> T06 | C25: =ROUND(SUMIFS(ENTRIES!$E$2:$E$2000,ENTRIES!$B$2:$B$2000,A25,ENTRIES!$G$2:$G$2000,"TRANSFER"),2) -> 0 | D25: =IF(ABS(C25)<0.005,"OK","CHECK") -> OK | E25: =COUNTIFS(ENTRIES!$B$2:$B$2000,A25,ENTRIES!$G$2:$G$2000,"TRANSFER") -> 2
A26: 701 | B26: =INDEX(ENTRIES!$A$2:$A$2000,MATCH(A26,ENTRIES!$B$2:$B$2000,0)) -> T07 | C26: =ROUND(SUMIFS(ENTRIES!$E$2:$E$2000,ENTRIES!$B$2:$B$2000,A26,ENTRIES!$G$2:$G$2000,"TRANSFER"),2) -> 0 | D26: =IF(ABS(C26)<0.005,"OK","CHECK") -> OK | E26: =COUNTIFS(ENTRIES!$B$2:$B$2000,A26,ENTRIES!$G$2:$G$2000,"TRANSFER") -> 2
A27: 801 | B27: =INDEX(ENTRIES!$A$2:$A$2000,MATCH(A27,ENTRIES!$B$2:$B$2000,0)) -> T08 | C27: =ROUND(SUMIFS(ENTRIES!$E$2:$E$2000,ENTRIES!$B$2:$B$2000,A27,ENTRIES!$G$2:$G$2000,"TRANSFER"),2) -> 0 | D27: =IF(ABS(C27)<0.005,"OK","CHECK") -> OK | E27: =COUNTIFS(ENTRIES!$B$2:$B$2000,A27,ENTRIES!$G$2:$G$2000,"TRANSFER") -> 2
A28: 901 | B28: =INDEX(ENTRIES!$A$2:$A$2000,MATCH(A28,ENTRIES!$B$2:$B$2000,0)) -> T09 | C28: =ROUND(SUMIFS(ENTRIES!$E$2:$E$2000,ENTRIES!$B$2:$B$2000,A28,ENTRIES!$G$2:$G$2000,"TRANSFER"),2) -> 0 | D28: =IF(ABS(C28)<0.005,"OK","CHECK") -> OK | E28: =COUNTIFS(ENTRIES!$B$2:$B$2000,A28,ENTRIES!$G$2:$G$2000,"TRANSFER") -> 2
A29: 1001 | B29: =INDEX(ENTRIES!$A$2:$A$2000,MATCH(A29,ENTRIES!$B$2:$B$2000,0)) -> T10 | C29: =ROUND(SUMIFS(ENTRIES!$E$2:$E$2000,ENTRIES!$B$2:$B$2000,A29,ENTRIES!$G$2:$G$2000,"TRANSFER"),2) -> 0 | D29: =IF(ABS(C29)<0.005,"OK","CHECK") -> OK | E29: =COUNTIFS(ENTRIES!$B$2:$B$2000,A29,ENTRIES!$G$2:$G$2000,"TRANSFER") -> 2
... A78: 9710 | B78: =INDEX(ENTRIES!$A$2:$A$2000,MATCH(A78,ENTRIES!$B$2:$B$2000,0)) -> B0 | C78: =ROUND(SUMIFS(ENTRIES!$E$2:$E$2000,ENTRIES!$B$2:$B$2000,A78,ENTRIES!$G$2:$G$2000,"TRANSFER"),2) -> 0 | D78: =IF(ABS(C78)<0.005,"OK","CHECK") -> OK | E78: =COUNTIFS(ENTRIES!$B$2:$B$2000,A78,ENTRIES!$G$2:$G$2000,"TRANSFER") -> 2
A81: Check 3 · TRANSFER sum per month
A82: month | C82: TRANSFER sum | D82: status | E82: explanation when not zero
A83: 2025-10 | C83: =ROUND(SUMIFS(ENTRIES!$E$2:$E$2000,ENTRIES!$O$2:$O$2000,A83,ENTRIES!$G$2:$G$2000,"TRANSFER"),2) -> 0 | D83: =IF(ABS(C83)<0.005,"OK","REVIEW") -> OK | E83: =IF(D83="OK","","Look for pairs with legs in different months")
A84: 2025-11 | C84: =ROUND(SUMIFS(ENTRIES!$E$2:$E$2000,ENTRIES!$O$2:$O$2000,A84,ENTRIES!$G$2:$G$2000,"TRANSFER"),2) -> 0 | D84: =IF(ABS(C84)<0.005,"OK","REVIEW") -> OK | E84: =IF(D84="OK","","Look for pairs with legs in different months")
A85: 2025-12 | C85: =ROUND(SUMIFS(ENTRIES!$E$2:$E$2000,ENTRIES!$O$2:$O$2000,A85,ENTRIES!$G$2:$G$2000,"TRANSFER"),2) -> 0 | D85: =IF(ABS(C85)<0.005,"OK","REVIEW") -> OK | E85: =IF(D85="OK","","Look for pairs with legs in different months")
A86: 2026-01 | C86: =ROUND(SUMIFS(ENTRIES!$E$2:$E$2000,ENTRIES!$O$2:$O$2000,A86,ENTRIES!$G$2:$G$2000,"TRANSFER"),2) -> -500 | D86: =IF(ABS(C86)<0.005,"OK","REVIEW") -> REVIEW | E86: =IF(D86="OK","","Look for pairs with legs in different months") -> Look for pairs with legs in different months
A87: 2026-02 | C87: =ROUND(SUMIFS(ENTRIES!$E$2:$E$2000,ENTRIES!$O$2:$O$2000,A87,ENTRIES!$G$2:$G$2000,"TRANSFER"),2) -> 500 | D87: =IF(ABS(C87)<0.005,"OK","REVIEW") -> REVIEW | E87: =IF(D87="OK","","Look for pairs with legs in different months") -> Look for pairs with legs in different months
A88: 2026-03 | C88: =ROUND(SUMIFS(ENTRIES!$E$2:$E$2000,ENTRIES!$O$2:$O$2000,A88,ENTRIES!$G$2:$G$2000,"TRANSFER"),2) -> 0 | D88: =IF(ABS(C88)<0.005,"OK","REVIEW") -> OK | E88: =IF(D88="OK","","Look for pairs with legs in different months")
A89: 2026-04 | C89: =ROUND(SUMIFS(ENTRIES!$E$2:$E$2000,ENTRIES!$O$2:$O$2000,A89,ENTRIES!$G$2:$G$2000,"TRANSFER"),2) -> 0 | D89: =IF(ABS(C89)<0.005,"OK","REVIEW") -> OK | E89: =IF(D89="OK","","Look for pairs with legs in different months")
A90: 2026-05 | C90: =ROUND(SUMIFS(ENTRIES!$E$2:$E$2000,ENTRIES!$O$2:$O$2000,A90,ENTRIES!$G$2:$G$2000,"TRANSFER"),2) -> 0 | D90: =IF(ABS(C90)<0.005,"OK","REVIEW") -> OK | E90: =IF(D90="OK","","Look for pairs with legs in different months")
A91: 2026-06 | C91: =ROUND(SUMIFS(ENTRIES!$E$2:$E$2000,ENTRIES!$O$2:$O$2000,A91,ENTRIES!$G$2:$G$2000,"TRANSFER"),2) -> 0 | D91: =IF(ABS(C91)<0.005,"OK","REVIEW") -> OK | E91: =IF(D91="OK","","Look for pairs with legs in different months")
A94: Checks 4 and 6 · balance per source
A95: source | B95: what it is | C95: kind | D95: balance € | E95: local balance | F95: status
A96: BANK_CURRENT | B96: Current account | C96: =INDEX(CODES!$G$5:$G$30,MATCH(A96,CODES!$F$5:$F$30,0)) -> real | D96: =ROUND(SUMIFS(ENTRIES!$E$2:$E$2000,ENTRIES!$C$2:$C$2000,A96),2) -> 5373.96 | E96: =IF(LEFT(A96,5)="CASH_",IF(A96="CASH_EUR","",SUMIFS(ENTRIES!$K$2:$K$2000,ENTRIES!$C$2:$C$2000,A96)),IF(A96="MULTI_THB",SUMIFS(ENTRIES!$K$2:$K$2000,ENTRIES!$C$2:$C$2000,A96),"")) | F96: =IF(C96="helper",IF(ABS(D96)<0.005,"OK","CHECK"),"compare") -> compare
A97: BANK_SAVINGS | B97: Savings account | C97: =INDEX(CODES!$G$5:$G$30,MATCH(A97,CODES!$F$5:$F$30,0)) -> real | D97: =ROUND(SUMIFS(ENTRIES!$E$2:$E$2000,ENTRIES!$C$2:$C$2000,A97),2) -> 8485.3 | E97: =IF(LEFT(A97,5)="CASH_",IF(A97="CASH_EUR","",SUMIFS(ENTRIES!$K$2:$K$2000,ENTRIES!$C$2:$C$2000,A97)),IF(A97="MULTI_THB",SUMIFS(ENTRIES!$K$2:$K$2000,ENTRIES!$C$2:$C$2000,A97),"")) | F97: =IF(C97="helper",IF(ABS(D97)<0.005,"OK","CHECK"),"compare") -> compare
...

Sheet SUMMARY
A1: Summary
A2: Income, spending and net worth from ENTRIES. TRANSFER rows change none of these totals.
A4: line | B4: €
A5: Opening balances | B5: =SUMIFS(ENTRIES!$E$2:$E$2000,ENTRIES!$G$2:$G$2000,"OPENING_BALANCE") -> 17201.24
A6: Income (IN) | B6: =SUMIFS(ENTRIES!$E$2:$E$2000,ENTRIES!$G$2:$G$2000,"IN") -> 6407.3
A7: Spending, Europe (OUT) | B7: =SUMIFS(ENTRIES!$E$2:$E$2000,ENTRIES!$G$2:$G$2000,"OUT") -> -1059.25
A8: Spending, fixed (OUT_FIXED) | B8: =SUMIFS(ENTRIES!$E$2:$E$2000,ENTRIES!$G$2:$G$2000,"OUT_FIXED") -> -985.66
A9: Spending, Asia (OUT_ASIA*) | B9: =SUMIFS(ENTRIES!$E$2:$E$2000,ENTRIES!$G$2:$G$2000,"OUT_ASIA")+SUMIFS(ENTRIES!$E$2:$E$2000,ENTRIES!$G$2:$G$2000,"OUT_ASIA_FLIGHTS")+SUMIFS(ENTRIES!$E$2:$E$2000,ENTRIES!$G$2:$G$2000,"OUT_ASIA_INSURANCE")+SUMIFS(ENTRIES!$E$2:$E$2000,ENTRIES!$G$2:$G$2000,"OUT_ASIA_PREPAID") -> -3274.59
A10: Paper gains and losses | B10: =SUMIFS(ENTRIES!$E$2:$E$2000,ENTRIES!$G$2:$G$2000,"PAPER_GAIN_LOSS") -> -11.8
A11: Transfers (must be 0) | B11: =SUMIFS(ENTRIES!$E$2:$E$2000,ENTRIES!$G$2:$G$2000,"TRANSFER") -> 0
A12: Uncategorised | B12: =SUMIFS(ENTRIES!$E$2:$E$2000,ENTRIES!$G$2:$G$2000,"UNCATEGORISED") -> 0
A13: Net worth now (sum of all rows) | B13: =SUM(ENTRIES!$E$2:$E$2000) -> 18277.24
A14: Net worth from the lines above | B14: =SUM(B5:B12) -> 18277.24
A15: Difference (must be 0) | B15: =ROUND(B13-B14,2) -> 0
A17: Per month (sign of amount: costs are negative)
A18: month | B18: income | C18: Europe | D18: fixed | E18: Asia | F18: total spending | G18: transfers
A19: 2025-10 | B19: =SUMIFS(ENTRIES!$E$2:$E$2000,ENTRIES!$O$2:$O$2000,A19,ENTRIES!$G$2:$G$2000,"IN") -> 0 | C19: =SUMIFS(ENTRIES!$E$2:$E$2000,ENTRIES!$O$2:$O$2000,A19,ENTRIES!$G$2:$G$2000,"OUT") -> 0 | D19: =SUMIFS(ENTRIES!$E$2:$E$2000,ENTRIES!$O$2:$O$2000,A19,ENTRIES!$G$2:$G$2000,"OUT_FIXED") -> 0 | E19: =(SUMIFS(ENTRIES!$E$2:$E$2000,ENTRIES!$O$2:$O$2000,A19,ENTRIES!$G$2:$G$2000,"OUT_ASIA")+SUMIFS(ENTRIES!$E$2:$E$2000,ENTRIES!$O$2:$O$2000,A19,ENTRIES!$G$2:$G$2000,"OUT_ASIA_FLIGHTS")+SUMIFS(ENTRIES!$E$2:$E$2000,ENTRIES!$O$2:$O$2000,A19,ENTRIES!$G$2:$G$2000,"OUT_ASIA_INSURANCE")+SUMIFS(ENTRIES!$E$2:$E$2000,ENTRIES!$O$2:$O$2000,A19,ENTRIES!$G$2:$G$2000,"OUT_ASIA_PREPAID")) -> 0 | F19: =SUM(C19:E19) -> 0 | G19: =SUMIFS(ENTRIES!$E$2:$E$2000,ENTRIES!$O$2:$O$2000,A19,ENTRIES!$G$2:$G$2000,"TRANSFER") -> 0
A20: 2025-11 | B20: =SUMIFS(ENTRIES!$E$2:$E$2000,ENTRIES!$O$2:$O$2000,A20,ENTRIES!$G$2:$G$2000,"IN") -> 0 | C20: =SUMIFS(ENTRIES!$E$2:$E$2000,ENTRIES!$O$2:$O$2000,A20,ENTRIES!$G$2:$G$2000,"OUT") -> -18.9 | D20: =SUMIFS(ENTRIES!$E$2:$E$2000,ENTRIES!$O$2:$O$2000,A20,ENTRIES!$G$2:$G$2000,"OUT_FIXED") -> -112.77 | E20: =(SUMIFS(ENTRIES!$E$2:$E$2000,ENTRIES!$O$2:$O$2000,A20,ENTRIES!$G$2:$G$2000,"OUT_ASIA")+SUMIFS(ENTRIES!$E$2:$E$2000,ENTRIES!$O$2:$O$2000,A20,ENTRIES!$G$2:$G$2000,"OUT_ASIA_FLIGHTS")+SUMIFS(ENTRIES!$E$2:$E$2000,ENTRIES!$O$2:$O$2000,A20,ENTRIES!$G$2:$G$2000,"OUT_ASIA_INSURANCE")+SUMIFS(ENTRIES!$E$2:$E$2000,ENTRIES!$O$2:$O$2000,A20,ENTRIES!$G$2:$G$2000,"OUT_ASIA_PREPAID")) -> -1258.41 | F20: =SUM(C20:E20) -> -1390.08 | G20: =SUMIFS(ENTRIES!$E$2:$E$2000,ENTRIES!$O$2:$O$2000,A20,ENTRIES!$G$2:$G$2000,"TRANSFER") -> 0
A21: 2025-12 | B21: =SUMIFS(ENTRIES!$E$2:$E$2000,ENTRIES!$O$2:$O$2000,A21,ENTRIES!$G$2:$G$2000,"IN") -> 0 | C21: =SUMIFS(ENTRIES!$E$2:$E$2000,ENTRIES!$O$2:$O$2000,A21,ENTRIES!$G$2:$G$2000,"OUT") -> -0.45 | D21: =SUMIFS(ENTRIES!$E$2:$E$2000,ENTRIES!$O$2:$O$2000,A21,ENTRIES!$G$2:$G$2000,"OUT_FIXED") -> -112.77 | E21: =(SUMIFS(ENTRIES!$E$2:$E$2000,ENTRIES!$O$2:$O$2000,A21,ENTRIES!$G$2:$G$2000,"OUT_ASIA")+SUMIFS(ENTRIES!$E$2:$E$2000,ENTRIES!$O$2:$O$2000,A21,ENTRIES!$G$2:$G$2000,"OUT_ASIA_FLIGHTS")+SUMIFS(ENTRIES!$E$2:$E$2000,ENTRIES!$O$2:$O$2000,A21,ENTRIES!$G$2:$G$2000,"OUT_ASIA_INSURANCE")+SUMIFS(ENTRIES!$E$2:$E$2000,ENTRIES!$O$2:$O$2000,A21,ENTRIES!$G$2:$G$2000,"OUT_ASIA_PREPAID")) -> -381.69 | F21: =SUM(C21:E21) -> -494.91 | G21: =SUMIFS(ENTRIES!$E$2:$E$2000,ENTRIES!$O$2:$O$2000,A21,ENTRIES!$G$2:$G$2000,"TRANSFER") -> 0
A22: 2026-01 | B22: =SUMIFS(ENTRIES!$E$2:$E$2000,ENTRIES!$O$2:$O$2000,A22,ENTRIES!$G$2:$G$2000,"IN") -> 148.2 | C22: =SUMIFS(ENTRIES!$E$2:$E$2000,ENTRIES!$O$2:$O$2000,A22,ENTRIES!$G$2:$G$2000,"OUT") -> 0 | D22: =SUMIFS(ENTRIES!$E$2:$E$2000,ENTRIES!$O$2:$O$2000,A22,ENTRIES!$G$2:$G$2000,"OUT_FIXED") -> -112.77 | E22: =(SUMIFS(ENTRIES!$E$2:$E$2000,ENTRIES!$O$2:$O$2000,A22,ENTRIES!$G$2:$G$2000,"OUT_ASIA")+SUMIFS(ENTRIES!$E$2:$E$2000,ENTRIES!$O$2:$O$2000,A22,ENTRIES!$G$2:$G$2000,"OUT_ASIA_FLIGHTS")+SUMIFS(ENTRIES!$E$2:$E$2000,ENTRIES!$O$2:$O$2000,A22,ENTRIES!$G$2:$G$2000,"OUT_ASIA_INSURANCE")+SUMIFS(ENTRIES!$E$2:$E$2000,ENTRIES!$O$2:$O$2000,A22,ENTRIES!$G$2:$G$2000,"OUT_ASIA_PREPAID")) -> -461.51 | F22: =SUM(C22:E22) -> -574.28 | G22: =SUMIFS(ENTRIES!$E$2:$E$2000,ENTRIES!$O$2:$O$2000,A22,ENTRIES!$G$2:$G$2000,"TRANSFER") -> -500
A23: 2026-02 | B23: =SUMIFS(ENTRIES!$E$2:$E$2000,ENTRIES!$O$2:$O$2000,A23,ENTRIES!$G$2:$G$2000,"IN") -> 0 | C23: =SUMIFS(ENTRIES!$E$2:$E$2000,ENTRIES!$O$2:$O$2000,A23,ENTRIES!$G$2:$G$2000,"OUT") -> 0 | D23: =SUMIFS(ENTRIES!$E$2:$E$2000,ENTRIES!$O$2:$O$2000,A23,ENTRIES!$G$2:$G$2000,"OUT_FIXED") -> -208.77 | E23: =(SUMIFS(ENTRIES!$E$2:$E$2000,ENTRIES!$O$2:$O$2000,A23,ENTRIES!$G$2:$G$2000,"OUT_ASIA")+SUMIFS(ENTRIES!$E$2:$E$2000,ENTRIES!$O$2:$O$2000,A23,ENTRIES!$G$2:$G$2000,"OUT_ASIA_FLIGHTS")+SUMIFS(ENTRIES!$E$2:$E$2000,ENTRIES!$O$2:$O$2000,A23,ENTRIES!$G$2:$G$2000,"OUT_ASIA_INSURANCE")+SUMIFS(ENTRIES!$E$2:$E$2000,ENTRIES!$O$2:$O$2000,A23,ENTRIES!$G$2:$G$2000,"OUT_ASIA_PREPAID")) -> -353.28 | F23: =SUM(C23:E23) -> -562.05 | G23: =SUMIFS(ENTRIES!$E$2:$E$2000,ENTRIES!$O$2:$O$2000,A23,ENTRIES!$G$2:$G$2000,"TRANSFER") -> 500
A24: 2026-03 | B24: =SUMIFS(ENTRIES!$E$2:$E$2000,ENTRIES!$O$2:$O$2000,A24,ENTRIES!$G$2:$G$2000,"IN") -> 412 | C24: =SUMIFS(ENTRIES!$E$2:$E$2000,ENTRIES!$O$2:$O$2000,A24,ENTRIES!$G$2:$G$2000,"OUT") -> 0 | D24: =SUMIFS(ENTRIES!$E$2:$E$2000,ENTRIES!$O$2:$O$2000,A24,ENTRIES!$G$2:$G$2000,"OUT_FIXED") -> -112.77 | E24: =(SUMIFS(ENTRIES!$E$2:$E$2000,ENTRIES!$O$2:$O$2000,A24,ENTRIES!$G$2:$G$2000,"OUT_ASIA")+SUMIFS(ENTRIES!$E$2:$E$2000,ENTRIES!$O$2:$O$2000,A24,ENTRIES!$G$2:$G$2000,"OUT_ASIA_FLIGHTS")+SUMIFS(ENTRIES!$E$2:$E$2000,ENTRIES!$O$2:$O$2000,A24,ENTRIES!$G$2:$G$2000,"OUT_ASIA_INSURANCE")+SUMIFS(ENTRIES!$E$2:$E$2000,ENTRIES!$O$2:$O$2000,A24,ENTRIES!$G$2:$G$2000,"OUT_ASIA_PREPAID")) -> -404.6 | F24: =SUM(C24:E24) -> -517.37 | G24: =SUMIFS(ENTRIES!$E$2:$E$2000,ENTRIES!$O$2:$O$2000,A24,ENTRIES!$G$2:$G$2000,"TRANSFER") -> 0
A25: 2026-04 | B25: =SUMIFS(ENTRIES!$E$2:$E$2000,ENTRIES!$O$2:$O$2000,A25,ENTRIES!$G$2:$G$2000,"IN") -> 1487.1 | C25: =SUMIFS(ENTRIES!$E$2:$E$2000,ENTRIES!$O$2:$O$2000,A25,ENTRIES!$G$2:$G$2000,"OUT") -> -136.49 | D25: =SUMIFS(ENTRIES!$E$2:$E$2000,ENTRIES!$O$2:$O$2000,A25,ENTRIES!$G$2:$G$2000,"OUT_FIXED") -> -112.77 | E25: =(SUMIFS(ENTRIES!$E$2:$E$2000,ENTRIES!$O$2:$O$2000,A25,ENTRIES!$G$2:$G$2000,"OUT_ASIA")+SUMIFS(ENTRIES!$E$2:$E$2000,ENTRIES!$O$2:$O$2000,A25,ENTRIES!$G$2:$G$2000,"OUT_ASIA_FLIGHTS")+SUMIFS(ENTRIES!$E$2:$E$2000,ENTRIES!$O$2:$O$2000,A25,ENTRIES!$G$2:$G$2000,"OUT_ASIA_INSURANCE")+SUMIFS(ENTRIES!$E$2:$E$2000,ENTRIES!$O$2:$O$2000,A25,ENTRIES!$G$2:$G$2000,"OUT_ASIA_PREPAID")) -> -195.1 | F25: =SUM(C25:E25) -> -444.36 | G25: =SUMIFS(ENTRIES!$E$2:$E$2000,ENTRIES!$O$2:$O$2000,A25,ENTRIES!$G$2:$G$2000,"TRANSFER") -> 0
A26: 2026-05 | B26: =SUMIFS(ENTRIES!$E$2:$E$2000,ENTRIES!$O$2:$O$2000,A26,ENTRIES!$G$2:$G$2000,"IN") -> 2150 | C26: =SUMIFS(ENTRIES!$E$2:$E$2000,ENTRIES!$O$2:$O$2000,A26,ENTRIES!$G$2:$G$2000,"OUT") -> -636.69 | D26: =SUMIFS(ENTRIES!$E$2:$E$2000,ENTRIES!$O$2:$O$2000,A26,ENTRIES!$G$2:$G$2000,"OUT_FIXED") -> -100.27 | E26: =(SUMIFS(ENTRIES!$E$2:$E$2000,ENTRIES!$O$2:$O$2000,A26,ENTRIES!$G$2:$G$2000,"OUT_ASIA")+SUMIFS(ENTRIES!$E$2:$E$2000,ENTRIES!$O$2:$O$2000,A26,ENTRIES!$G$2:$G$2000,"OUT_ASIA_FLIGHTS")+SUMIFS(ENTRIES!$E$2:$E$2000,ENTRIES!$O$2:$O$2000,A26,ENTRIES!$G$2:$G$2000,"OUT_ASIA_INSURANCE")+SUMIFS(ENTRIES!$E$2:$E$2000,ENTRIES!$O$2:$O$2000,A26,ENTRIES!$G$2:$G$2000,"OUT_ASIA_PREPAID")) -> -220 | F26: =SUM(C26:E26) -> -956.96 | G26: =SUMIFS(ENTRIES!$E$2:$E$2000,ENTRIES!$O$2:$O$2000,A26,ENTRIES!$G$2:$G$2000,"TRANSFER") -> 0
A27: 2026-06 | B27: =SUMIFS(ENTRIES!$E$2:$E$2000,ENTRIES!$O$2:$O$2000,A27,ENTRIES!$G$2:$G$2000,"IN") -> 2210 | C27: =SUMIFS(ENTRIES!$E$2:$E$2000,ENTRIES!$O$2:$O$2000,A27,ENTRIES!$G$2:$G$2000,"OUT") -> -266.72 | D27: =SUMIFS(ENTRIES!$E$2:$E$2000,ENTRIES!$O$2:$O$2000,A27,ENTRIES!$G$2:$G$2000,"OUT_FIXED") -> -112.77 | E27: =(SUMIFS(ENTRIES!$E$2:$E$2000,ENTRIES!$O$2:$O$2000,A27,ENTRIES!$G$2:$G$2000,"OUT_ASIA")+SUMIFS(ENTRIES!$E$2:$E$2000,ENTRIES!$O$2:$O$2000,A27,ENTRIES!$G$2:$G$2000,"OUT_ASIA_FLIGHTS")+SUMIFS(ENTRIES!$E$2:$E$2000,ENTRIES!$O$2:$O$2000,A27,ENTRIES!$G$2:$G$2000,"OUT_ASIA_INSURANCE")+SUMIFS(ENTRIES!$E$2:$E$2000,ENTRIES!$O$2:$O$2000,A27,ENTRIES!$G$2:$G$2000,"OUT_ASIA_PREPAID")) -> 0 | F27: =SUM(C27:E27) -> -379.49 | G27: =SUMIFS(ENTRIES!$E$2:$E$2000,ENTRIES!$O$2:$O$2000,A27,ENTRIES!$G$2:$G$2000,"TRANSFER") -> 0
A28: Total | B28: =SUM(B19:B27) -> 6407.3 | C28: =SUM(C19:C27) -> -1059.25 | D28: =SUM(D19:D27) -> -985.66 | E28: =SUM(E19:E27) -> -3274.59 | F28: =SUM(F19:F27) -> -5319.5 | G28: =SUM(G19:G27) -> 0

Sheet CODES
A1: Code lists
A2: These lists feed the dropdowns on ENTRIES. Add a code here before using it there.
A4: type | B4: meaning | D4: group | F4: source | G4: kind | H4: what it is | J4: daily_code | K4: meaning
A5: IN | B5: Income: earned or received for keeps | D5: SALARY | F5: BANK_CURRENT | G5: real | H5: Current account | J5: bf | K5: Breakfast
A6: OUT | B6: Spending, Netherlands and Europe | D6: TAX_REFUNDS | F6: BANK_SAVINGS | G6: real | H6: Savings account | J6: l | K6: Lunch
A7: OUT_FIXED | B7: Fixed costs, all year | D7: INTEREST | F7: BANK_PENSION | G7: real | H7: Pension savings, locked until retirement | J7: d | K7: Dinner
A8: OUT_ASIA | B8: Daily life in Asia | D8: MISC_IN | F8: CREDIT_CARD | G8: real | H8: Credit card | J8: c | K8: Coffee
A9: OUT_ASIA_FLIGHTS | B9: Flights to and from Asia | D9: GROCERIES | F9: FOREIGN_BANK | G9: real | H9: Small account abroad | J9: s | K9: Snacks and drinks
A10: OUT_ASIA_INSURANCE | B10: Travel insurance | D10: EATING_OUT | F10: MULTI_EUR | G10: real | H10: Multi-currency app, EUR pocket | J10: alc | K10: Alcohol
A11: OUT_ASIA_PREPAID | B11: Visa, vaccinations, paid before leaving | D11: MISC | F11: MULTI_THB | G11: real | H11: Multi-currency app, THB pocket | J11: h | K11: Housing
A12: TRANSFER | B12: Money moving between my own sources; must net to zero | D12: CLOTHING_CARE | F12: BANK_ONLINE | G12: real | H12: Online bank / money-transfer service | J12: scoot | K12: Scooter
A13: OPENING_BALANCE | B13: Opening balance or zero-amount checkpoint | D13: TRAVEL_NL | F13: ONLINE_WALLET | G13: real | H13: Online payment wallet | J13: taxi | K13: Taxi or ride-hailing
A14: PAPER_GAIN_LOSS | B14: Revaluation, e.g. crypto | D14: TRAVEL_EUROPE | F14: CASH_EUR | G14: real | H14: Cash, euro | J14: tix | K14: Bus, train, ferry
A15: UNCATEGORISED | B15: Imported, not yet labelled | D15: FIXED_COSTS | F15: CASH_THB | G15: real | H15: Cash, Thai baht | J15: yoga | K15: Classes
D16: ASIA_DAILY | F16: CASH_VND | G16: real | H16: Cash, Vietnamese dong | J16: lndry | K16: Laundry
D17: ASIA_MISC | F17: CASH_USD | G17: real | H17: Cash, US dollar | J17: tour | K17: Sights
D18: ASIA_FLIGHTS | F18: CASH_AED | G18: real | H18: Cash, UAE dirham | J18: tip | K18: Tips
D19: ASIA_PREP | F19: CRYPTO | G19: real | H19: Crypto holding | J19: visa | K19: Visa extension
D20: PREPAID_UNUSED | F20: RECEIVABLES | G20: helper | H20: Owed to me by an organisation | J20: misc | K20: Everything else
D21: TRANSFER | F21: PAYABLES | G21: helper | H21: I owe someone | J21: diff | K21: Cash count difference
D22: OPENING_BALANCE | F22: PREPAID | G22: helper | H22: Services paid ahead | J22: in | K22: Cash coming in
D23: PAPER_GAIN_LOSS | F23: DEPOSITS | G23: helper | H23: Deposits held by landlords and rentals
F24: INSURER_POT | G24: helper | H24: Deductible instalments with insurer
F25: PERSON_A | G25: helper | H25: Loans to and from one friend
F26: TAB_FRIEND_B | G26: helper | H26: Cash with a friend who pays by QR
F27: FX_DIFF | G27: helper | H27: Rounding differences on repayments
F28: RECLASS | G28: helper | H28: Moves between categories
F29: SUSPENSE | G29: helper | H29: Money not yet placed
F30: STATS_ONLY | G30: helper | H30: Zero-amount rows with local details

Sheet WHEREABOUTS
A1: Location | B1: Country | C1: Work | D1: Arrival | E1: days
A2: Hometown | B2: NL | C2: =FALSE() -> FALSE | D2: 45931 | E2: =D3-D2 -> 34
A3: Dubai airport | B3: AE | C3: =FALSE() -> FALSE | D3: 45965 | E3: =D4-D3 -> 1
A4: Chiang Mai | B4: TH | C4: =FALSE() -> FALSE | D4: 45966 | E4: =D5-D4 -> 26
A5: Koh Phangan | B5: TH | C5: =FALSE() -> FALSE | D5: 45992 | E5: =D6-D5 -> 31
A6: Hoi An | B6: VN | C6: =FALSE() -> FALSE | D6: 46023 | E6: =D7-D6 -> 109
A7: Hometown | B7: NL | C7: =FALSE() -> FALSE | D7: 46132 | E7: =D8-D7 -> 11
A8: Campsite job | B8: NL | C8: =TRUE() -> TRUE | D8: 46143
A10: One row per arrival. A stay lasts until the day before the next arrival; the last one runs to the end of the ledger. Country is the two-letter code; every country outside Europe counts as a stay in Asia. Work is TRUE for a stay where I had a job.
